2023-08-04 13:48:56,423 - WARNING - root - initialized Divar object
2023-08-04 13:48:56,424 - WARNING - Divar - starting the loop
2023-08-04 13:49:27,778 - INFO - Divar - scraping info from https://divar.ir/v/%D8%A7%D9%BE%D8%A7%D8%B1%D8%AA%D9%85%D8%A7%D9%86-%DB%B7%DB%B1-%D9%85%D8%AA%D8%B1%DB%8C-%D8%AA%D9%85%DB%8C%D8%B2-%D9%88%D8%AE%D9%88%D8%B4-%D9%86%D9%82%D8%B4%D9%87_%D8%A2%D9%BE%D8%A7%D8%B1%D8%AA%D9%85%D8%A7%D9%86_%D8%AA%D9%87%D8%B1%D8%A7%D9%86_%D8%AF%D9%88%D9%84%D8%A7%D8%A8_%D8%AF%DB%8C%D9%88%D8%A7%D8%B1/AZM3cHOK
2023-08-04 13:50:43,690 - WARNING - urllib3.connectionpool - Retrying (Retry(total=2, connect=None, read=None, redirect=None, status=None)) after connection broken by 'NewConnectionError('<urllib3.connection.HTTPConnection object at 0x7f2f5d53c1d0>: Failed to establish a new connection: [Errno 111] Connection refused')': /session/55e21147-8de6-44da-8b7f-7d3d79b332ae/elements
2023-08-04 13:50:43,699 - WARNING - urllib3.connectionpool - Retrying (Retry(total=1, connect=None, read=None, redirect=None, status=None)) after connection broken by 'NewConnectionError('<urllib3.connection.HTTPConnection object at 0x7f2f5d53c8d0>: Failed to establish a new connection: [Errno 111] Connection refused')': /session/55e21147-8de6-44da-8b7f-7d3d79b332ae/elements
2023-08-04 13:50:43,700 - WARNING - urllib3.connectionpool - Retrying (Retry(total=0, connect=None, read=None, redirect=None, status=None)) after connection broken by 'NewConnectionError('<urllib3.connection.HTTPConnection object at 0x7f2f5d53d090>: Failed to establish a new connection: [Errno 111] Connection refused')': /session/55e21147-8de6-44da-8b7f-7d3d79b332ae/elements
2023-08-04 13:50:43,702 - ERROR - Divar - we have a Error in scanner: HTTPConnectionPool(host='localhost', port=43899): Max retries exceeded with url: /session/55e21147-8de6-44da-8b7f-7d3d79b332ae/elements (Caused by NewConnectionError('<urllib3.connection.HTTPConnection object at 0x7f2f5d53d810>: Failed to establish a new connection: [Errno 111] Connection refused'))
Traceback (most recent call last):
  File "/home/alireza/__Projects__/Amlak_dev/listing/scripts/divar/divar.py", line 126, in post_details
    base_row_value_a_tag = self.driver.find_elements(By.XPATH, "//a[@class='kt-unexpandable-row__action kt-text-truncate']")
                           ^^^^^^^^^^^^^^^^^^^^^^^^^^^^^^^^^^^^^^^^^^^^^^^^^^^^^^^^^^^^^^^^^^^^^^^^^^^^^^^^^^^^^^^^^^^^^^^^^
  File "/home/alireza/__Projects__/Amlak/.venv/lib/python3.11/site-packages/selenium/webdriver/remote/webdriver.py", line 860, in find_elements
    return self.execute(Command.FIND_ELEMENTS, {"using": by, "value": value})["value"] or []
           ^^^^^^^^^^^^^^^^^^^^^^^^^^^^^^^^^^^^^^^^^^^^^^^^^^^^^^^^^^^^^^^^^^
  File "/home/alireza/__Projects__/Amlak/.venv/lib/python3.11/site-packages/selenium/webdriver/remote/webdriver.py", line 438, in execute
    response = self.command_executor.execute(driver_command, params)
               ^^^^^^^^^^^^^^^^^^^^^^^^^^^^^^^^^^^^^^^^^^^^^^^^^^^^^
  File "/home/alireza/__Projects__/Amlak/.venv/lib/python3.11/site-packages/selenium/webdriver/remote/remote_connection.py", line 290, in execute
    return self._request(command_info[0], url, body=data)
           ^^^^^^^^^^^^^^^^^^^^^^^^^^^^^^^^^^^^^^^^^^^^^^
  File "/home/alireza/__Projects__/Amlak/.venv/lib/python3.11/site-packages/selenium/webdriver/remote/remote_connection.py", line 311, in _request
    response = self._conn.request(method, url, body=body, headers=headers)
               ^^^^^^^^^^^^^^^^^^^^^^^^^^^^^^^^^^^^^^^^^^^^^^^^^^^^^^^^^^^
  File "/home/alireza/__Projects__/Amlak/.venv/lib/python3.11/site-packages/urllib3/request.py", line 78, in request
    return self.request_encode_body(
           ^^^^^^^^^^^^^^^^^^^^^^^^^
  File "/home/alireza/__Projects__/Amlak/.venv/lib/python3.11/site-packages/urllib3/request.py", line 170, in request_encode_body
    return self.urlopen(method, url, **extra_kw)
           ^^^^^^^^^^^^^^^^^^^^^^^^^^^^^^^^^^^^^
  File "/home/alireza/__Projects__/Amlak/.venv/lib/python3.11/site-packages/urllib3/poolmanager.py", line 376, in urlopen
    response = conn.urlopen(method, u.request_uri, **kw)
               ^^^^^^^^^^^^^^^^^^^^^^^^^^^^^^^^^^^^^^^^^
  File "/home/alireza/__Projects__/Amlak/.venv/lib/python3.11/site-packages/urllib3/connectionpool.py", line 703, in urlopen
    httplib_response = self._make_request(
                       ^^^^^^^^^^^^^^^^^^^
  File "/home/alireza/__Projects__/Amlak/.venv/lib/python3.11/site-packages/urllib3/connectionpool.py", line 449, in _make_request
    six.raise_from(e, None)
  File "<string>", line 3, in raise_from
  File "/home/alireza/__Projects__/Amlak/.venv/lib/python3.11/site-packages/urllib3/connectionpool.py", line 444, in _make_request
    httplib_response = conn.getresponse()
                       ^^^^^^^^^^^^^^^^^^
  File "/usr/lib/python3.11/http/client.py", line 1375, in getresponse
    response.begin()
  File "/usr/lib/python3.11/http/client.py", line 318, in begin
    version, status, reason = self._read_status()
                              ^^^^^^^^^^^^^^^^^^^
  File "/usr/lib/python3.11/http/client.py", line 279, in _read_status
    line = str(self.fp.readline(_MAXLINE + 1), "iso-8859-1")
               ^^^^^^^^^^^^^^^^^^^^^^^^^^^^^^
  File "/usr/lib/python3.11/socket.py", line 706, in readinto
    return self._sock.recv_into(b)
           ^^^^^^^^^^^^^^^^^^^^^^^
KeyboardInterrupt

During handling of the above exception, another exception occurred:

Traceback (most recent call last):
  File "/home/alireza/__Projects__/Amlak/.venv/lib/python3.11/site-packages/urllib3/connection.py", line 174, in _new_conn
    conn = connection.create_connection(
           ^^^^^^^^^^^^^^^^^^^^^^^^^^^^^
  File "/home/alireza/__Projects__/Amlak/.venv/lib/python3.11/site-packages/urllib3/util/connection.py", line 95, in create_connection
    raise err
  File "/home/alireza/__Projects__/Amlak/.venv/lib/python3.11/site-packages/urllib3/util/connection.py", line 85, in create_connection
    sock.connect(sa)
ConnectionRefusedError: [Errno 111] Connection refused

During handling of the above exception, another exception occurred:

Traceback (most recent call last):
  File "/home/alireza/__Projects__/Amlak/.venv/lib/python3.11/site-packages/urllib3/connectionpool.py", line 703, in urlopen
    httplib_response = self._make_request(
                       ^^^^^^^^^^^^^^^^^^^
  File "/home/alireza/__Projects__/Amlak/.venv/lib/python3.11/site-packages/urllib3/connectionpool.py", line 398, in _make_request
    conn.request(method, url, **httplib_request_kw)
  File "/home/alireza/__Projects__/Amlak/.venv/lib/python3.11/site-packages/urllib3/connection.py", line 239, in request
    super(HTTPConnection, self).request(method, url, body=body, headers=headers)
  File "/usr/lib/python3.11/http/client.py", line 1283, in request
    self._send_request(method, url, body, headers, encode_chunked)
  File "/usr/lib/python3.11/http/client.py", line 1329, in _send_request
    self.endheaders(body, encode_chunked=encode_chunked)
  File "/usr/lib/python3.11/http/client.py", line 1278, in endheaders
    self._send_output(message_body, encode_chunked=encode_chunked)
  File "/usr/lib/python3.11/http/client.py", line 1038, in _send_output
    self.send(msg)
  File "/usr/lib/python3.11/http/client.py", line 976, in send
    self.connect()
  File "/home/alireza/__Projects__/Amlak/.venv/lib/python3.11/site-packages/urllib3/connection.py", line 205, in connect
    conn = self._new_conn()
           ^^^^^^^^^^^^^^^^
  File "/home/alireza/__Projects__/Amlak/.venv/lib/python3.11/site-packages/urllib3/connection.py", line 186, in _new_conn
    raise NewConnectionError(
urllib3.exceptions.NewConnectionError: <urllib3.connection.HTTPConnection object at 0x7f2f5d53d810>: Failed to establish a new connection: [Errno 111] Connection refused

During handling of the above exception, another exception occurred:

Traceback (most recent call last):
  File "/home/alireza/__Projects__/Amlak_dev/listing/scripts/listing/listing_temp.py", line 259, in scanner
    self.searcher(post=post_id)
  File "/home/alireza/__Projects__/Amlak_dev/listing/scripts/listing/listing_temp.py", line 223, in searcher
    res = self.divar_obj.post_details(file)
          ^^^^^^^^^^^^^^^^^^^^^^^^^^^^^^^^^
  File "/home/alireza/__Projects__/Amlak_dev/listing/scripts/divar/divar.py", line 135, in post_details
    base_row_value = self.driver.find_elements(By.XPATH, "//p[@class='kt-unexpandable-row__value']")
                     ^^^^^^^^^^^^^^^^^^^^^^^^^^^^^^^^^^^^^^^^^^^^^^^^^^^^^^^^^^^^^^^^^^^^^^^^^^^^^^^
  File "/home/alireza/__Projects__/Amlak/.venv/lib/python3.11/site-packages/selenium/webdriver/remote/webdriver.py", line 860, in find_elements
    return self.execute(Command.FIND_ELEMENTS, {"using": by, "value": value})["value"] or []
           ^^^^^^^^^^^^^^^^^^^^^^^^^^^^^^^^^^^^^^^^^^^^^^^^^^^^^^^^^^^^^^^^^^
  File "/home/alireza/__Projects__/Amlak/.venv/lib/python3.11/site-packages/selenium/webdriver/remote/webdriver.py", line 438, in execute
    response = self.command_executor.execute(driver_command, params)
               ^^^^^^^^^^^^^^^^^^^^^^^^^^^^^^^^^^^^^^^^^^^^^^^^^^^^^
  File "/home/alireza/__Projects__/Amlak/.venv/lib/python3.11/site-packages/selenium/webdriver/remote/remote_connection.py", line 290, in execute
    return self._request(command_info[0], url, body=data)
           ^^^^^^^^^^^^^^^^^^^^^^^^^^^^^^^^^^^^^^^^^^^^^^
  File "/home/alireza/__Projects__/Amlak/.venv/lib/python3.11/site-packages/selenium/webdriver/remote/remote_connection.py", line 311, in _request
    response = self._conn.request(method, url, body=body, headers=headers)
               ^^^^^^^^^^^^^^^^^^^^^^^^^^^^^^^^^^^^^^^^^^^^^^^^^^^^^^^^^^^
  File "/home/alireza/__Projects__/Amlak/.venv/lib/python3.11/site-packages/urllib3/request.py", line 78, in request
    return self.request_encode_body(
           ^^^^^^^^^^^^^^^^^^^^^^^^^
  File "/home/alireza/__Projects__/Amlak/.venv/lib/python3.11/site-packages/urllib3/request.py", line 170, in request_encode_body
    return self.urlopen(method, url, **extra_kw)
           ^^^^^^^^^^^^^^^^^^^^^^^^^^^^^^^^^^^^^
  File "/home/alireza/__Projects__/Amlak/.venv/lib/python3.11/site-packages/urllib3/poolmanager.py", line 376, in urlopen
    response = conn.urlopen(method, u.request_uri, **kw)
               ^^^^^^^^^^^^^^^^^^^^^^^^^^^^^^^^^^^^^^^^^
  File "/home/alireza/__Projects__/Amlak/.venv/lib/python3.11/site-packages/urllib3/connectionpool.py", line 815, in urlopen
    return self.urlopen(
           ^^^^^^^^^^^^^
  File "/home/alireza/__Projects__/Amlak/.venv/lib/python3.11/site-packages/urllib3/connectionpool.py", line 815, in urlopen
    return self.urlopen(
           ^^^^^^^^^^^^^
  File "/home/alireza/__Projects__/Amlak/.venv/lib/python3.11/site-packages/urllib3/connectionpool.py", line 815, in urlopen
    return self.urlopen(
           ^^^^^^^^^^^^^
  File "/home/alireza/__Projects__/Amlak/.venv/lib/python3.11/site-packages/urllib3/connectionpool.py", line 787, in urlopen
    retries = retries.increment(
              ^^^^^^^^^^^^^^^^^^
  File "/home/alireza/__Projects__/Amlak/.venv/lib/python3.11/site-packages/urllib3/util/retry.py", line 592, in increment
    raise MaxRetryError(_pool, url, error or ResponseError(cause))
urllib3.exceptions.MaxRetryError: HTTPConnectionPool(host='localhost', port=43899): Max retries exceeded with url: /session/55e21147-8de6-44da-8b7f-7d3d79b332ae/elements (Caused by NewConnectionError('<urllib3.connection.HTTPConnection object at 0x7f2f5d53d810>: Failed to establish a new connection: [Errno 111] Connection refused'))
